[2024-05-26T17:06:29.329+0000] {local_task_job_runner.py:120} INFO - ::group::Pre task execution logs
[2024-05-26T17:06:29.356+0000] {taskinstance.py:2076} INFO - Dependencies all met for dep_context=non-requeueable deps ti=<TaskInstance: upload_file_to_cloud_storage_dag.upload_file_to_cloud_storage_task manual__2024-05-26T17:06:27.540196+00:00 [queued]>
[2024-05-26T17:06:29.370+0000] {taskinstance.py:2076} INFO - Dependencies all met for dep_context=requeueable deps ti=<TaskInstance: upload_file_to_cloud_storage_dag.upload_file_to_cloud_storage_task manual__2024-05-26T17:06:27.540196+00:00 [queued]>
[2024-05-26T17:06:29.371+0000] {taskinstance.py:2306} INFO - Starting attempt 1 of 3
[2024-05-26T17:06:29.398+0000] {taskinstance.py:2330} INFO - Executing <Task(PythonOperator): upload_file_to_cloud_storage_task> on 2024-05-26 17:06:27.540196+00:00
[2024-05-26T17:06:29.407+0000] {standard_task_runner.py:90} INFO - Running: ['***', 'tasks', 'run', 'upload_file_to_cloud_storage_dag', 'upload_file_to_cloud_storage_task', 'manual__2024-05-26T17:06:27.540196+00:00', '--job-id', '63', '--raw', '--subdir', 'DAGS_FOLDER/testis.py', '--cfg-path', '/tmp/tmpwhckxkeb']
[2024-05-26T17:06:29.411+0000] {standard_task_runner.py:91} INFO - Job 63: Subtask upload_file_to_cloud_storage_task
[2024-05-26T17:06:29.415+0000] {logging_mixin.py:188} WARNING - /home/***/.local/lib/python3.12/site-packages/***/task/task_runner/standard_task_runner.py:61 DeprecationWarning: This process (pid=664) is multi-threaded, use of fork() may lead to deadlocks in the child.
[2024-05-26T17:06:29.416+0000] {standard_task_runner.py:63} INFO - Started process 665 to run task
[2024-05-26T17:06:29.485+0000] {task_command.py:426} INFO - Running <TaskInstance: upload_file_to_cloud_storage_dag.upload_file_to_cloud_storage_task manual__2024-05-26T17:06:27.540196+00:00 [running]> on host 4ff5ec95d398
[2024-05-26T17:06:29.629+0000] {taskinstance.py:2648} INFO - Exporting env vars: AIRFLOW_CTX_DAG_OWNER='data_engineer' AIRFLOW_CTX_DAG_ID='upload_file_to_cloud_storage_dag' AIRFLOW_CTX_TASK_ID='upload_file_to_cloud_storage_task' AIRFLOW_CTX_EXECUTION_DATE='2024-05-26T17:06:27.540196+00:00' AIRFLOW_CTX_TRY_NUMBER='1' AIRFLOW_CTX_DAG_RUN_ID='manual__2024-05-26T17:06:27.540196+00:00'
[2024-05-26T17:06:29.632+0000] {taskinstance.py:430} INFO - ::endgroup::
[2024-05-26T17:06:29.701+0000] {base.py:84} INFO - Using connection ID '***s3' for task execution.
[2024-05-26T17:06:29.703+0000] {connection_wrapper.py:387} INFO - AWS Connection (conn_id='***s3', conn_type='aws') credentials retrieved from extra.
[2024-05-26T17:06:31.224+0000] {taskinstance.py:441} INFO - ::group::Post task execution logs
[2024-05-26T17:06:31.231+0000] {taskinstance.py:2905} ERROR - Task failed with exception
Traceback (most recent call last):
  File "/home/airflow/.local/lib/python3.12/site-packages/airflow/models/taskinstance.py", line 465, in _execute_task
    result = _execute_callable(context=context, **execute_callable_kwargs)
             ^^^^^^^^^^^^^^^^^^^^^^^^^^^^^^^^^^^^^^^^^^^^^^^^^^^^^^^^^^^^^
  File "/home/airflow/.local/lib/python3.12/site-packages/airflow/models/taskinstance.py", line 432, in _execute_callable
    return execute_callable(context=context, **execute_callable_kwargs)
           ^^^^^^^^^^^^^^^^^^^^^^^^^^^^^^^^^^^^^^^^^^^^^^^^^^^^^^^^^^^^
  File "/home/airflow/.local/lib/python3.12/site-packages/airflow/models/baseoperator.py", line 400, in wrapper
    return func(self, *args, **kwargs)
           ^^^^^^^^^^^^^^^^^^^^^^^^^^^
  File "/home/airflow/.local/lib/python3.12/site-packages/airflow/operators/python.py", line 235, in execute
    return_value = self.execute_callable()
                   ^^^^^^^^^^^^^^^^^^^^^^^
  File "/home/airflow/.local/lib/python3.12/site-packages/airflow/operators/python.py", line 252, in execute_callable
    return self.python_callable(*self.op_args, **self.op_kwargs)
           ^^^^^^^^^^^^^^^^^^^^^^^^^^^^^^^^^^^^^^^^^^^^^^^^^^^^^
  File "/opt/airflow/dags/testis.py", line 22, in upload_file_to_cloud_storage
    cloud_storage_service.load_file(filename=file_to_upload, key=cloud_storage_key, bucket_name=cloud_storage_bucket, replace=True)
  File "/home/airflow/.local/lib/python3.12/site-packages/airflow/providers/amazon/aws/hooks/s3.py", line 135, in wrapper
    return func(*bound_args.args, **bound_args.kwargs)
           ^^^^^^^^^^^^^^^^^^^^^^^^^^^^^^^^^^^^^^^^^^^
  File "/home/airflow/.local/lib/python3.12/site-packages/airflow/providers/amazon/aws/hooks/s3.py", line 89, in wrapper
    return func(*bound_args.args, **bound_args.kwargs)
           ^^^^^^^^^^^^^^^^^^^^^^^^^^^^^^^^^^^^^^^^^^^
  File "/home/airflow/.local/lib/python3.12/site-packages/airflow/providers/amazon/aws/hooks/s3.py", line 1098, in load_file
    client.upload_file(filename, bucket_name, key, ExtraArgs=extra_args, Config=self.transfer_config)
  File "/home/airflow/.local/lib/python3.12/site-packages/boto3/s3/inject.py", line 145, in upload_file
    return transfer.upload_file(
           ^^^^^^^^^^^^^^^^^^^^^
  File "/home/airflow/.local/lib/python3.12/site-packages/boto3/s3/transfer.py", line 371, in upload_file
    future.result()
  File "/home/airflow/.local/lib/python3.12/site-packages/s3transfer/futures.py", line 103, in result
    return self._coordinator.result()
           ^^^^^^^^^^^^^^^^^^^^^^^^^^
  File "/home/airflow/.local/lib/python3.12/site-packages/s3transfer/futures.py", line 266, in result
    raise self._exception
  File "/home/airflow/.local/lib/python3.12/site-packages/s3transfer/tasks.py", line 269, in _main
    self._submit(transfer_future=transfer_future, **kwargs)
  File "/home/airflow/.local/lib/python3.12/site-packages/s3transfer/upload.py", line 591, in _submit
    upload_input_manager.provide_transfer_size(transfer_future)
  File "/home/airflow/.local/lib/python3.12/site-packages/s3transfer/upload.py", line 244, in provide_transfer_size
    self._osutil.get_file_size(transfer_future.meta.call_args.fileobj)
  File "/home/airflow/.local/lib/python3.12/site-packages/s3transfer/utils.py", line 256, in get_file_size
    return os.path.getsize(filename)
           ^^^^^^^^^^^^^^^^^^^^^^^^^
  File "<frozen genericpath>", line 62, in getsize
FileNotFoundError: [Errno 2] No such file or directory: '/opt/airflow/dags/source/Private-HE-Dataset.csv'
[2024-05-26T17:06:31.517+0000] {taskinstance.py:1206} INFO - Marking task as UP_FOR_RETRY. dag_id=upload_file_to_cloud_storage_dag, task_id=upload_file_to_cloud_storage_task, run_id=manual__2024-05-26T17:06:27.540196+00:00, execution_date=20240526T170627, start_date=20240526T170629, end_date=20240526T170631
[2024-05-26T17:06:31.555+0000] {standard_task_runner.py:110} ERROR - Failed to execute job 63 for task upload_file_to_cloud_storage_task ([Errno 2] No such file or directory: '/opt/airflow/dags/source/Private-HE-Dataset.csv'; 665)
[2024-05-26T17:06:31.603+0000] {local_task_job_runner.py:240} INFO - Task exited with return code 1
[2024-05-26T17:06:31.739+0000] {taskinstance.py:3498} INFO - 0 downstream tasks scheduled from follow-on schedule check
[2024-05-26T17:06:31.744+0000] {local_task_job_runner.py:222} INFO - ::endgroup::
