[2024-06-02T12:50:26.364+0000] {task_context_logger.py:104} ERROR - Executor reports task instance <TaskInstance: upload_file_to_cloud_storage_dag.upload_file_to_cloud_storage_task manual__2024-06-02T12:50:21.590775+00:00 [queued]> finished (failed) although the task says it's queued. (Info: None) Was the task killed externally?
