[2024-06-09T06:45:35.755+0000] {local_task_job_runner.py:120} INFO - ::group::Pre task execution logs
[2024-06-09T06:45:35.784+0000] {taskinstance.py:2076} INFO - Dependencies all met for dep_context=non-requeueable deps ti=<TaskInstance: upload_files_to_cloud_storage_dag.upload_files_to_cloud_storage_task manual__2024-06-09T06:45:34.616863+00:00 [queued]>
[2024-06-09T06:45:35.804+0000] {taskinstance.py:2076} INFO - Dependencies all met for dep_context=requeueable deps ti=<TaskInstance: upload_files_to_cloud_storage_dag.upload_files_to_cloud_storage_task manual__2024-06-09T06:45:34.616863+00:00 [queued]>
[2024-06-09T06:45:35.805+0000] {taskinstance.py:2306} INFO - Starting attempt 1 of 3
[2024-06-09T06:45:35.828+0000] {taskinstance.py:2330} INFO - Executing <Task(PythonOperator): upload_files_to_cloud_storage_task> on 2024-06-09 06:45:34.616863+00:00
[2024-06-09T06:45:35.846+0000] {standard_task_runner.py:90} INFO - Running: ['***', 'tasks', 'run', 'upload_files_to_cloud_storage_dag', 'upload_files_to_cloud_storage_task', 'manual__2024-06-09T06:45:34.616863+00:00', '--job-id', '132', '--raw', '--subdir', 'DAGS_FOLDER/input.py', '--cfg-path', '/tmp/tmpqd91ca_j']
[2024-06-09T06:45:35.859+0000] {standard_task_runner.py:91} INFO - Job 132: Subtask upload_files_to_cloud_storage_task
[2024-06-09T06:45:35.868+0000] {logging_mixin.py:188} WARNING - /home/***/.local/lib/python3.12/site-packages/***/task/task_runner/standard_task_runner.py:61 DeprecationWarning: This process (pid=413) is multi-threaded, use of fork() may lead to deadlocks in the child.
[2024-06-09T06:45:35.869+0000] {standard_task_runner.py:63} INFO - Started process 414 to run task
[2024-06-09T06:45:35.933+0000] {task_command.py:426} INFO - Running <TaskInstance: upload_files_to_cloud_storage_dag.upload_files_to_cloud_storage_task manual__2024-06-09T06:45:34.616863+00:00 [running]> on host f69b53e362bb
[2024-06-09T06:45:36.045+0000] {taskinstance.py:2648} INFO - Exporting env vars: AIRFLOW_CTX_DAG_OWNER='data_engineer' AIRFLOW_CTX_DAG_ID='upload_files_to_cloud_storage_dag' AIRFLOW_CTX_TASK_ID='upload_files_to_cloud_storage_task' AIRFLOW_CTX_EXECUTION_DATE='2024-06-09T06:45:34.616863+00:00' AIRFLOW_CTX_TRY_NUMBER='1' AIRFLOW_CTX_DAG_RUN_ID='manual__2024-06-09T06:45:34.616863+00:00'
[2024-06-09T06:45:36.046+0000] {taskinstance.py:430} INFO - ::endgroup::
[2024-06-09T06:45:36.076+0000] {base.py:84} INFO - Using connection ID '***s3' for task execution.
[2024-06-09T06:45:36.077+0000] {connection_wrapper.py:387} INFO - AWS Connection (conn_id='***s3', conn_type='aws') credentials retrieved from extra.
[2024-06-09T06:45:36.474+0000] {taskinstance.py:441} INFO - ::group::Post task execution logs
[2024-06-09T06:45:36.475+0000] {taskinstance.py:2905} ERROR - Task failed with exception
Traceback (most recent call last):
  File "/home/airflow/.local/lib/python3.12/site-packages/boto3/s3/transfer.py", line 371, in upload_file
    future.result()
  File "/home/airflow/.local/lib/python3.12/site-packages/s3transfer/futures.py", line 103, in result
    return self._coordinator.result()
           ^^^^^^^^^^^^^^^^^^^^^^^^^^
  File "/home/airflow/.local/lib/python3.12/site-packages/s3transfer/futures.py", line 266, in result
    raise self._exception
  File "/home/airflow/.local/lib/python3.12/site-packages/s3transfer/tasks.py", line 139, in __call__
    return self._execute_main(kwargs)
           ^^^^^^^^^^^^^^^^^^^^^^^^^^
  File "/home/airflow/.local/lib/python3.12/site-packages/s3transfer/tasks.py", line 162, in _execute_main
    return_value = self._main(**kwargs)
                   ^^^^^^^^^^^^^^^^^^^^
  File "/home/airflow/.local/lib/python3.12/site-packages/s3transfer/upload.py", line 764, in _main
    client.put_object(Bucket=bucket, Key=key, Body=body, **extra_args)
  File "/home/airflow/.local/lib/python3.12/site-packages/botocore/client.py", line 553, in _api_call
    return self._make_api_call(operation_name, kwargs)
           ^^^^^^^^^^^^^^^^^^^^^^^^^^^^^^^^^^^^^^^^^^^
  File "/home/airflow/.local/lib/python3.12/site-packages/botocore/client.py", line 1009, in _make_api_call
    raise error_class(parsed_response, operation_name)
botocore.errorfactory.NoSuchBucket: An error occurred (NoSuchBucket) when calling the PutObject operation: The specified bucket does not exist

During handling of the above exception, another exception occurred:

Traceback (most recent call last):
  File "/home/airflow/.local/lib/python3.12/site-packages/airflow/models/taskinstance.py", line 465, in _execute_task
    result = _execute_callable(context=context, **execute_callable_kwargs)
             ^^^^^^^^^^^^^^^^^^^^^^^^^^^^^^^^^^^^^^^^^^^^^^^^^^^^^^^^^^^^^
  File "/home/airflow/.local/lib/python3.12/site-packages/airflow/models/taskinstance.py", line 432, in _execute_callable
    return execute_callable(context=context, **execute_callable_kwargs)
           ^^^^^^^^^^^^^^^^^^^^^^^^^^^^^^^^^^^^^^^^^^^^^^^^^^^^^^^^^^^^
  File "/home/airflow/.local/lib/python3.12/site-packages/airflow/models/baseoperator.py", line 400, in wrapper
    return func(self, *args, **kwargs)
           ^^^^^^^^^^^^^^^^^^^^^^^^^^^
  File "/home/airflow/.local/lib/python3.12/site-packages/airflow/operators/python.py", line 235, in execute
    return_value = self.execute_callable()
                   ^^^^^^^^^^^^^^^^^^^^^^^
  File "/home/airflow/.local/lib/python3.12/site-packages/airflow/operators/python.py", line 252, in execute_callable
    return self.python_callable(*self.op_args, **self.op_kwargs)
           ^^^^^^^^^^^^^^^^^^^^^^^^^^^^^^^^^^^^^^^^^^^^^^^^^^^^^
  File "/opt/airflow/dags/input.py", line 23, in upload_files_to_cloud_storage
    cloud_storage_service.load_file(filename=file_to_upload, key=cloud_storage_key, bucket_name=cloud_storage_bucket, replace=True)
  File "/home/airflow/.local/lib/python3.12/site-packages/airflow/providers/amazon/aws/hooks/s3.py", line 135, in wrapper
    return func(*bound_args.args, **bound_args.kwargs)
           ^^^^^^^^^^^^^^^^^^^^^^^^^^^^^^^^^^^^^^^^^^^
  File "/home/airflow/.local/lib/python3.12/site-packages/airflow/providers/amazon/aws/hooks/s3.py", line 89, in wrapper
    return func(*bound_args.args, **bound_args.kwargs)
           ^^^^^^^^^^^^^^^^^^^^^^^^^^^^^^^^^^^^^^^^^^^
  File "/home/airflow/.local/lib/python3.12/site-packages/airflow/providers/amazon/aws/hooks/s3.py", line 1098, in load_file
    client.upload_file(filename, bucket_name, key, ExtraArgs=extra_args, Config=self.transfer_config)
  File "/home/airflow/.local/lib/python3.12/site-packages/boto3/s3/inject.py", line 145, in upload_file
    return transfer.upload_file(
           ^^^^^^^^^^^^^^^^^^^^^
  File "/home/airflow/.local/lib/python3.12/site-packages/boto3/s3/transfer.py", line 377, in upload_file
    raise S3UploadFailedError(
boto3.exceptions.S3UploadFailedError: Failed to upload /opt/***/dags/source/pengangguran-berdasarkan-tingkat-pendidikan-2020.xlsx to ***/pengangguran-berdasarkan-tingkat-pendidikan-2020.xlsx: An error occurred (NoSuchBucket) when calling the PutObject operation: The specified bucket does not exist
[2024-06-09T06:45:36.493+0000] {taskinstance.py:1206} INFO - Marking task as UP_FOR_RETRY. dag_id=upload_files_to_cloud_storage_dag, task_id=upload_files_to_cloud_storage_task, run_id=manual__2024-06-09T06:45:34.616863+00:00, execution_date=20240609T064534, start_date=20240609T064535, end_date=20240609T064536
[2024-06-09T06:45:36.519+0000] {standard_task_runner.py:110} ERROR - Failed to execute job 132 for task upload_files_to_cloud_storage_task (Failed to upload /opt/***/dags/source/pengangguran-berdasarkan-tingkat-pendidikan-2020.xlsx to ***/pengangguran-berdasarkan-tingkat-pendidikan-2020.xlsx: An error occurred (NoSuchBucket) when calling the PutObject operation: The specified bucket does not exist; 414)
[2024-06-09T06:45:36.566+0000] {local_task_job_runner.py:240} INFO - Task exited with return code 1
[2024-06-09T06:45:36.585+0000] {taskinstance.py:3498} INFO - 0 downstream tasks scheduled from follow-on schedule check
[2024-06-09T06:45:36.590+0000] {local_task_job_runner.py:222} INFO - ::endgroup::
